<?xml version="1.0"?>

<root xmlns:xacro="http://ros.org/wiki/xacro">

  <xacro:property name="PI" value="3.1415926535897931" />

  <xacro:macro name="wheel" params="prefix parent *origin visual_angle">
    <joint name="${parent}_${prefix}_wheel_joint" type="continuous">
      <xacro:insert_block name="origin" />
      <axis xyz="0 1 0" />
      <anchor xyz="0 0 0" />
      <limit effort="100" velocity="100" />
      <parent link="${parent}" />
      <child link="${prefix}_wheel_link" />
    </joint>

    <link name="${prefix}_wheel_link">
      <inertial>
        <mass value="5" />
        <origin xyz=" 0 0 0 " />
        <inertia  ixx="0.076" ixy="0.0" ixz="0.0"
                  iyy="0.144" iyz="0.0"
                  izz="0.076" />
      </inertial>
      <visual>
        <!--<origin xyz="0 0 0" rpy="0 0 ${visual_angle}" />-->
        <origin xyz="0 0 0" rpy="${PI/2} 0 0" />
        <geometry>
          <!--<mesh filename="package://iri_objects_description/meshes/wheel.dae" scale="0.0254 0.0254 0.0254"/>-->
          <cylinder length="0.1" radius="0.24"/>
        </geometry>
        <material name="black"/>
      </visual>
      <collision>
        <origin xyz="0 0 0" rpy="${PI/2} 0 0" />
        <geometry>
          <cylinder length="0.001" radius="0.24"/>
        </geometry>
      </collision>
    </link>
    
    <transmission name="${prefix}_wheel_trans">
      <type>transmission_interface/SimpleTransmission</type>
      <joint name="${parent}_${prefix}_wheel_joint">
        <hardwareInterface>EffortJointInterface</hardwareInterface>
      </joint>
      <actuator name="${prefix}_wheel_motor">
        <hardwareInterface>EffortJointInterface</hardwareInterface>
        <mechanicalReduction>1</mechanicalReduction>
      </actuator>
    </transmission>

    <gazebo reference="${parent}_${prefix}_wheel_joint">
      <dynamics damping="0.7" friction="0.2" />
    </gazebo>

    <gazebo reference="${prefix}_wheel_link">
      <gravity>true</gravity>
      <self_collide>false</self_collide>
      <mu1 value="10.0" />
      <mu2 value="10.0" />
      <kp  value="1000000.0" />
      <kd  value="1.0" />
      <material>Gazebo/DarkGrey</material>
    </gazebo>
    
  </xacro:macro>
</root>
